import { STRICT } from '../helpers/constants.js';
import { createIterator } from '../helpers/helpers.js';

import Iterator from '@core-js/pure/es/iterator';

QUnit.test('Iterator#drop', assert => {
  const { drop } = Iterator.prototype;

  assert.isFunction(drop);
  assert.arity(drop, 1);
  assert.nonEnumerable(Iterator.prototype, 'drop');

  assert.arrayEqual(drop.call(createIterator([1, 2, 3]), 1).toArray(), [2, 3], 'basic functionality');
  assert.arrayEqual(drop.call(createIterator([1, 2, 3]), 1.5).toArray(), [2, 3], 'float');
  assert.arrayEqual(drop.call(createIterator([1, 2, 3]), 4).toArray(), [], 'big');
  assert.arrayEqual(drop.call(createIterator([1, 2, 3]), 0).toArray(), [1, 2, 3], 'zero');

  if (STRICT) {
    assert.throws(() => drop.call(undefined, 1), TypeError);
    assert.throws(() => drop.call(null, 1), TypeError);
  }

  assert.throws(() => drop.call({}, 1).next(), TypeError);
  assert.throws(() => drop.call([], 1).next(), TypeError);
  assert.throws(() => drop.call(createIterator([1, 2, 3]), -1), RangeError, 'negative');
  const it = createIterator([1], { return() { this.closed = true; } });
  assert.throws(() => drop.call(it, NaN), RangeError, 'NaN');
  assert.true(it.closed, "drop doesn't close iterator on validation error");
  // https://issues.chromium.org/issues/336839115
  assert.throws(() => drop.call({ next: null }, 0).next(), TypeError);
});
